/*
 * This file was automatically generated by EvoSuite
 * Tue Apr 26 16:42:01 GMT 2022
 */


import org.junit.Test;
import static org.junit.Assert.*;
import static org.evosuite.runtime.EvoAssertions.*;
import org.evosuite.runtime.EvoRunner;
import org.evosuite.runtime.EvoRunnerParameters;
import org.junit.runner.RunWith;

@RunWith(EvoRunner.class) @EvoRunnerParameters(mockJVMNonDeterminism = true, useVFS = true, useVNET = true, resetStaticState = true, separateClassLoader = true) 
public class Target_ESTest extends Target_ESTest_scaffolding {

  @Test(timeout = 4000)
  public void test0()  throws Throwable  {
      Target target0 = new Target();
      // Undeclared exception!
      try { 
        target0.__target__(256, 4);
        fail("Expecting exception: AssertionError");
      
      } catch(AssertionError e) {
         //
         // no message in exception (getMessage() returned null)
         //
      }
  }

  @Test(timeout = 4000)
  public void test1()  throws Throwable  {
      Target target0 = new Target();
      // Undeclared exception!
      target0.__target__(1, 2029051800);
  }

  @Test(timeout = 4000)
  public void test2()  throws Throwable  {
      Target target0 = new Target();
      // Undeclared exception!
      try { 
        target0.__target__(89, 1206);
        fail("Expecting exception: AssertionError");
      
      } catch(AssertionError e) {
         //
         // no message in exception (getMessage() returned null)
         //
      }
  }

  @Test(timeout = 4000)
  public void test3()  throws Throwable  {
      Target target0 = new Target();
      int int0 = target0.__target__(0, 89);
      assertEquals(0, int0);
  }

  @Test(timeout = 4000)
  public void test4()  throws Throwable  {
      Target target0 = new Target();
      int int0 = target0.__target__(0, 0);
      assertEquals(1, int0);
  }

  @Test(timeout = 4000)
  public void test5()  throws Throwable  {
      Target target0 = new Target();
      // Undeclared exception!
      try { 
        target0.__target__(3514, (-941));
        fail("Expecting exception: AssertionError");
      
      } catch(AssertionError e) {
         //
         // no message in exception (getMessage() returned null)
         //
      }
  }

  @Test(timeout = 4000)
  public void test6()  throws Throwable  {
      Target target0 = new Target();
      // Undeclared exception!
      try { 
        target0.__target__((-1557), (-1));
        fail("Expecting exception: AssertionError");
      
      } catch(AssertionError e) {
         //
         // no message in exception (getMessage() returned null)
         //
      }
  }

  @Test(timeout = 4000)
  public void test7()  throws Throwable  {
      Target target0 = new Target();
      int int0 = target0.__target__(4, 4);
      assertEquals(256, int0);
  }
}
